Workbook
Name _Ref470001432: FR2_UC!$C$71
Name l_AssessorRating: List_Values!$B$12:$B$16
Name Rating: List_Values!$B$2:$B$5
Name SecurityLevels: 'SL Vector and Rating'!$B$7:$B$11

Sheet Guidance
A1: Overview: This template is designed to be used as a tool in carrying out Step 2 of the Product Security Assessment based on IEC 62443-4-2 . Step 2, Perform security evaluation, is carried out in a workshop with a qualified cyber security assessor (ABB Cyber Security Expert) and the Asset technical owner. The goal is to identify the gaps if the product does not meet the target SLs and present these findings to the product team.
A2: Sheet SL Vector and Rating: This sheet is used to record the SL-T Vector for the assessment of compliance to IEC 62443-4-2. In the simplest case, the product owner has specified one SL-T for the component.
A3: Sheets FR1_IAC, FR2_UC, FR3_SI, FR4_DC, FR5_RDF, FR6_TRE, FR7_RA are used to record the conformance status for each component requirement which is rated according to the following: supported supported with some restrictions/partly needs clarification not supported not applicable (needs strong justification!) In the Comments field it is expected that a statement describing the functionality of the product that provides the conformance along with reference(s). The product documentation references need to include descriptions of the supported functionality and how to configure it. The template can be used for each of the different types of components (SAR, EDR, HDR, NDR); also composite components. All CRs shall be filled in, where Not Applicable a justification shall be given. For the requirements that are specific for component types (SAR, EDR, HDR, NDR), any requirements that do not apply to the component under evaluation, are not filled in (these are left blank).
A4: Sheet Requirements gives the complete list of the Requirements along with the rating. This sheet is protected, data shall not be entered directly in this sheet.
A5: Sheet Summary is used to get a quick overview of the status (SL-C) for the selected SL-T. This sheet is protected, data shall not be entered directly in this sheet. Note that it is possible to filter out requirements that do not apply to the component type of the Component under Evaluation (e.g. if the product is a software application, use filtering to remove the EDR, NDR and HDR requirements from view).
A6: Definitions: SL-T, SL-C, SL-A
A7: SL-T - Security Level Target for a component. This is the target security capability level for the component. SL-C - Security Level Capability for a component. This is a statement of which security fucntionalities are supported, and can be used as a basis for compliance evalution/ certifications. SL-A -Security Level Achieved for a component that is configured and in operation in a plant. This is a statement of which capabilites have been configured (what is actually achieved when the component is put to use). evaluation of the SL-A can be used as a basis for evaluation of security of the component in operation.

Sheet SL Vector and Rating
A1: IEC/ISA 99 62443-4-2 Edition 1
A2: Security for industrial automation and control systems
A3: Part 4-2: Technical security requirements for IACS components
A4: Edition 1.0 | B4: 2019-02
B6: Security Levels | G6: IAC | H6: UC | I6: SI | J6: DC | K6: RDF | L6: TRE | M6: RA
A7: SL 0 | B7: No specific requirement or security protection necessary | C7: 0 | E7: SL-T Vector: | G7: =C16 -> 3 | H7: =C19 -> 3 | I7: =C22 -> 3 | J7: =C25 -> 3 | K7: =C28 -> 3 | L7: =C31 -> 3 | M7: =C34 -> 3
A8: SL 1 | B8: Protection against casual or coincidental violation | C8: 1 | E8: SL-C Vector Rating: | G8: =IF(G7='SL Vector and Rating'!$C$8,FR1_IAC!$F$7,(IF(G7='SL Vector and Rating'!$C$9,FR1_IAC!$G$7, (IF(G7='SL Vector and Rating'!$C$10,FR1_IAC!$H$7, (IF(G7='SL Vector and Rating'!$C$11,FR1_IAC!$I$7,"N/A"))))))) -> 2 | H8: =IF(H7='SL Vector and Rating'!$C$8,FR2_UC!$F$7,(IF(H7='SL Vector and Rating'!$C$9,FR2_UC!$G$7, (IF(H7='SL Vector and Rating'!$C$10,FR2_UC!$H$7, (IF(H7='SL Vector and Rating'!$C$11,FR2_UC!$I$7, "N/A"))))))) -> 2.3333333 | I8: =IF(I7='SL Vector and Rating'!$C$8,FR3_SI!$F$7,(IF(I7='SL Vector and Rating'!$C$9,FR3_SI!$G$7,(IF(I7='SL Vector and Rating'!$C$10,FR3_SI!$H$7, (IF(I7='SL Vector and Rating'!$C$11,FR3_SI!$I$7,"N/A"))))))) -> 2.6153846 | J8: =IF(J7='SL Vector and Rating'!$C$8,FR4_DC!$F$7,(IF(J7='SL Vector and Rating'!$C$9,FR4_DC!$G$7,(IF(J7='SL Vector and Rating'!$C$10,FR4_DC!$H$7, (IF(J7='SL Vector and Rating'!$C$11,FR4_DC!$I$7, "N/A"))))))) -> 2.5 | K8: =IF(K7='SL Vector and Rating'!$C$8,FR5_RDF!$F$7,(IF(K7='SL Vector and Rating'!$C$9,FR5_RDF!$G$7,(IF(K7='SL Vector and Rating'!$C$10,FR5_RDF!$H$7, (IF(K7='SL Vector and Rating'!$C$11,FR5_RDF!$I$7, "N/A"))))))) -> n/a | L8: =IF(L7='SL Vector and Rating'!$C$8,FR6_TRE!$F$7,(IF(L7='SL Vector and Rating'!$C$9,FR6_TRE!$G$7,(IF(L7='SL Vector and Rating'!$C$10,FR6_TRE!$H$7, (IF(L7='SL Vector and Rating'!$C$11,FR6_TRE!$I$7,"N/A"))))))) -> n/a | M8: =IF(M7='SL Vector and Rating'!$C$8,FR7_RA!$F$7,(IF(M7='SL Vector and Rating'!$C$9,FR7_RA!$G$7, (IF(M7='SL Vector and Rating'!$C$10,FR7_RA!$H$7, (IF(M7='SL Vector and Rating'!$C$11,FR7_RA!$I$7,"N/A"))))))) -> 3
A9: SL 2 | B9: Protection against intentional violation using simple means with low resources, generic skills, and low motivation | C9: 2
A10: SL 3 | B10: Protection against intentional violation using sophisticated means with moderate resources, IACS specific skills, and moderate motivation | C10: 3
A11: SL 4 | B11: Protection against intentional violation using sophisticated means with extended resources, IACS specific skills, and high motivation | C11: 4
A14: FR Targets | F14: FR | G14: Foundational requirements
A15: FR 1 - Identification and authentication control (IAC) | F15: IAC | G15: Identification and authentication control
A16: Security level: | B16: Protection against intentional violation using sophisticated means with moderate resources, IACS specific skills, and moderate motivation | C16: =IF(B16='SL Vector and Rating'!$B$7,'SL Vector and Rating'!$C$7,(IF(B16='SL Vector and Rating'!$B$8,'SL Vector and Rating'!$C$8,(IF(B16='SL Vector and Rating'!$B$9,'SL Vector and Rating'!$C$9,IF(B16='SL Vector and Rating'!$B$10,'SL Vector and Rating'!$C$10,(IF(B16='SL Vector and Rating'!$B$11,'SL Vector and Rating'!$C$11,'SL Vector and Rating'!$C$12)))))))) -> 3 | F16: UC | G16: Use control
F17: SI | G17: System integrity
A18: FR 2 - Use control (UC) | F18: DC | G18: Data confidentiality
A19: Security level: | B19: Protection against intentional violation using sophisticated means with moderate resources, IACS specific skills, and moderate motivation | C19: =IF(B19='SL Vector and Rating'!$B$7,'SL Vector and Rating'!$C$7,(IF(B19='SL Vector and Rating'!$B$8,'SL Vector and Rating'!$C$8,(IF(B19='SL Vector and Rating'!$B$9,'SL Vector and Rating'!$C$9,IF(B19='SL Vector and Rating'!$B$10,'SL Vector and Rating'!$C$10,(IF(B19='SL Vector and Rating'!$B$11,'SL Vector and Rating'!$C$11,'SL Vector and Rating'!$C$12)))))))) -> 3 | F19: RDF | G19: Restricted data flow
F20: TRE | G20: Timely response to events
A21: FR 3 - System integrity (SI) | F21: RA | G21: Resource availability
A22: Security level: | B22: Protection against intentional violation using sophisticated means with moderate resources, IACS specific skills, and moderate motivation | C22: =IF(B22='SL Vector and Rating'!$B$7,'SL Vector and Rating'!$C$7,(IF(B22='SL Vector and Rating'!$B$8,'SL Vector and Rating'!$C$8,(IF(B22='SL Vector and Rating'!$B$9,'SL Vector and Rating'!$C$9,IF(B22='SL Vector and Rating'!$B$10,'SL Vector and Rating'!$C$10,(IF(B22='SL Vector and Rating'!$B$11,'SL Vector and Rating'!$C$11,'SL Vector and Rating'!$C$12)))))))) -> 3 | J22: =IF(I22='SL Vector and Rating'!$B$7,'SL Vector and Rating'!$C$7,(IF(I22='SL Vector and Rating'!$B$8,'SL Vector and Rating'!$C$8,(IF(I22='SL Vector and Rating'!$B$9,'SL Vector and Rating'!$C$9,IF(I22='SL Vector and Rating'!$B$10,'SL Vector and Rating'!$C$10,(IF(I22='SL Vector and Rating'!$B$11,'SL Vector and Rating'!$C$11,'SL Vector and Rating'!$C$12))))))))
A24: FR 4 - Data confidentiality (DC)
A25: Security level: | B25: Protection against intentional violation using sophisticated means with moderate resources, IACS specific skills, and moderate motivation | C25: =IF(B25='SL Vector and Rating'!$B$7,'SL Vector and Rating'!$C$7,(IF(B25='SL Vector and Rating'!$B$8,'SL Vector and Rating'!$C$8,(IF(B25='SL Vector and Rating'!$B$9,'SL Vector and Rating'!$C$9,IF(B25='SL Vector and Rating'!$B$10,'SL Vector and Rating'!$C$10,(IF(B25='SL Vector and Rating'!$B$11,'SL Vector and Rating'!$C$11,'SL Vector and Rating'!$C$12)))))))) -> 3
A27: FR 5 - Restricted data flow (RDF)
A28: Security level: | B28: Protection against intentional violation using sophisticated means with moderate resources, IACS specific skills, and moderate motivation | C28: =IF(B28='SL Vector and Rating'!$B$7,'SL Vector and Rating'!$C$7,(IF(B28='SL Vector and Rating'!$B$8,'SL Vector and Rating'!$C$8,(IF(B28='SL Vector and Rating'!$B$9,'SL Vector and Rating'!$C$9,IF(B28='SL Vector and Rating'!$B$10,'SL Vector and Rating'!$C$10,(IF(B28='SL Vector and Rating'!$B$11,'SL Vector and Rating'!$C$11,'SL Vector and Rating'!$C$12)))))))) -> 3
A30: FR 6 - Timely response to events (TRE)
A31: Security level: | B31: Protection against intentional violation using sophisticated means with moderate resources, IACS specific skills, and moderate motivation | C31: =IF(B31='SL Vector and Rating'!$B$7,'SL Vector and Rating'!$C$7,(IF(B31='SL Vector and Rating'!$B$8,'SL Vector and Rating'!$C$8,(IF(B31='SL Vector and Rating'!$B$9,'SL Vector and Rating'!$C$9,IF(B31='SL Vector and Rating'!$B$10,'SL Vector and Rating'!$C$10,(IF(B31='SL Vector and Rating'!$B$11,'SL Vector and Rating'!$C$11,'SL Vector and Rating'!$C$12)))))))) -> 3
A33: FR 7 - Resource availability (RA)
A34: Security level: | B34: Protection against intentional violation using sophisticated means with moderate resources, IACS specific skills, and moderate motivation | C34: =IF(B34='SL Vector and Rating'!$B$7,'SL Vector and Rating'!$C$7,(IF(B34='SL Vector and Rating'!$B$8,'SL Vector and Rating'!$C$8,(IF(B34='SL Vector and Rating'!$B$9,'SL Vector and Rating'!$C$9,IF(B34='SL Vector and Rating'!$B$10,'SL Vector and Rating'!$C$10,(IF(B34='SL Vector and Rating'!$B$11,'SL Vector and Rating'!$C$11,'SL Vector and Rating'!$C$12)))))))) -> 3

Sheet Instructions
A1: Extracts from the IEC 62443 series of standards, including content related to requirements are under IEC copyright. The author thanks the International Electrotechnical Commission (IEC) for permission to reproduce Information from its International Standards. All such extracts are copyright of IEC, Geneva, Switzerland. All rights reserved. Further information on the IEC is available from www.iec.ch. IEC has no responsibility for the placement and context in which the extracts and contents are reproduced by the author, nor is IEC in any way responsible for the other content or accuracy therein.
A3: This workbook is intended as a compliance assessment tool for ABB Secure Development Life Cycle (SDLC) as well as for IEC 62443-4-1:2018. It uses Maturity Level 3.
A5: Assessment Information
B6: In this sheet the metadata about the assessment can be recorded.
A8: References
B9: In this sheet, reference document numbers and links can be listed that support the understanding of the assessment. It can be linked within the "Compliance Assessment" sheet by using the Reference ID, which could look like, e.g., #RID123
A10: Compliance Assessment
B11: This sheet contains all the relevant SDL requirements. Assessors can make comments about their findings and mark whether the requirements are considered fulfilled or not. With that information, compliance (or the compliance gap) can easily be documented by applying the respective filters.
B12: All requirements from IEC 62443 are itemized in the sense that more complex requirements are broken up into different pieces which the MCSR 2.0 project team considered atomic enough for an unambiguous assessment.
B14: In column A (category) all line items are categorized based on IEC 62443-4-1 practices as either SM, SR, SD, SI, SVV, DM, SUM, SG or ABB.
B15: SM => Security management The purpose of the security management practice is to ensure that the security-related activities are adequately planned, documented and executed throughout the product’s life-cycle.
B17: SR => Specification of security requirements The processes specified by this practice are used to document the security capabilities that are required for a product along with the expected product security context.
B19: SD => Secure by design The processes specified by this practice are used to ensure that the product is secure by design including defense in depth.
B21: SI => Secure implementation The processes specified by this practice are used to ensure that the product features are implemented securely.
B23: SVV => Secure verification and validation testing The processes specified by this practice are used to document the security testing required to ensure that all the security requirements have been met for the product and that security of the product is maintained when it is used in its product security context and configured to employ its defense in depth strategy.
B25: DM => Management of security-related issues The processes specified by this practice are used for handling security-related issues of a product that has been configured to employ its defense in depth strategy within the product security context.
B27: SUM => Security update management The processes specified by this practice are used to ensure that security updates associated with the product are tested for regressions and made available to product users in a timely manner.
B29: SG => Security guidelines The processes specified by this practice are used to provide user documentation that describes how to integrate, configure, and maintain the defense in depth strategy of the product in accordance with its product security context.
B31: ABB => ABB specific requirements There are a few minimum cyber security requirements which are ABB specific and which are not included in IEC 62443 and therefore cannot be expressed in IEC 62443 language.
... B61: Columns M (MCSR 1.0 Mapping) contains the MCSR 1.0 for Products item that is equivalent to the IEC 62443-4-1 requirement.
A63: Guideline
B64: Below is a step by step instruction on how to perform a security assessment. Step 1-4 are typically completed by the product development project/organization before shared with the assessor but can also be completed together with assessor.
B66: 1. Decide the scope of assessment: product release or product organization by adding data to "Assessment information" tab.
B67: 2. Select the security level of the assessment; ABB MCSR or ABB MCSR & full IEC 62443-4-1 by applying the filter of J1 cell of column M.
B68: 3. Provide argument/evidence for fulfillment in column F and initial compliance rating in column H. Different arguments are expected depending on the assessmnet scope defined in step #1. For a product release the arguments should focus on product artifacts being created during execution of the processes. As an example this can be the documented threat model for SR-2. If the assessment scope is not an specific product but the product organization, the arguments to be provided are the defined processes covering the specific requirement and optionally also the maturity level: Defined ML-2), Practiced (ML-3, ML-4).
B69: 4. Repeat step #2 for all requirements of the sheet.
B70: 5. Assessor reviews argument/evidence in column and compliance rating provided by the product organization and adds assessor comments in column G.
B71: 6. Assessor approves assessment if not any gaps are identified.

Sheet Requirements
A1: ID | B1: Title | C1: Rating | D1: Source | E1: Foundational requirements | F1: Req ID | G1: BR/RE | H1: System requirements | I1: Requirement description | J1: SL-C | K1: Comments | L1: Standard | M1: Req.1 | N1: Req.2 | O1: References | P1: Req ID Formula | Q1: Comment | R1: Ref. Status
A2: 1 | B2: =CONCATENATE(L2," - ",N2," ",M2) -> IEC 62443-4-2 - 1.1 CR | C2: =FR1_IAC!D11 -> 0 | D2: IEC62443-4-2 | E2: =FR1_IAC!A$7 -> FR 1 - Identification and authentication control (IAC) | F2: 1.01 CR | G2: =IF(ISNUMBER(SEARCH(" ",M2)),CONCATENATE("RE(",RIGHT(N2),")"),"n/a") -> n/a | H2: =FR1_IAC!C9 -> Human user identification and authentication | I2: =FR1_IAC!C10 -> Components shall provide the capability to identify and authenticate all human users according to ISA‑62443‑3‑3 SR 1.1 on all interfaces capable of human user access. This capability shall enforce such identification and authentication on all interfaces that provide human user access to the component to support segregation of duties and least privilege in accordance with applicable security policies and procedures. This capability may be provided locally by the component or by integration into a system level identification and authentication system. Note: Applicable security policies are a local matter. | J2: =FR1_IAC!J11 -> 1 | K2: =FR1_IAC!D10 -> 0 | L2: IEC 62443-4-2 | M2: =FR1_IAC!A9 -> CR | N2: =FR1_IAC!B9 -> 1.1 | O2: No | P2: =IF(ISNUMBER(SEARCH(" ",M2)),CONCATENATE(MID(N2,1,LEN(N2)-2)," ",LEFT(M2,FIND(" ",M2)-1)),CONCATENATE(N2," ",M2)) -> 1.1 CR
A3: 2 | B3: =CONCATENATE(L3," - ",N3," ",M3) -> IEC 62443-4-2 - 1.1.1 CR RE | C3: =FR1_IAC!D14 -> 0 | D3: IEC62443-4-2 | E3: =E2 -> FR 1 - Identification and authentication control (IAC) | F3: 1.01 CR | G3: =IF(ISNUMBER(SEARCH(" ",M3)),CONCATENATE("RE(",RIGHT(N3),")"),"n/a") -> RE(1) | H3: =FR1_IAC!C12 -> Unique identification and authentication | I3: =FR1_IAC!C13 -> Components shall provide the capability to uniquely identify and authenticate all human users | J3: =FR1_IAC!J14 -> 2 | K3: =FR1_IAC!D13 -> 0 | L3: IEC 62443-4-2 | M3: =FR1_IAC!A12 -> CR RE | N3: =FR1_IAC!B12 -> 1.1.1 | O3: No | P3: =IF(ISNUMBER(SEARCH(" ",M3)),CONCATENATE(MID(N3,1,LEN(N3)-2)," ",LEFT(M3,FIND(" ",M3)-1)),CONCATENATE(N3," ",M3)) -> 1.1 CR
A4: 3 | B4: =CONCATENATE(L4," - ",N4," ",M4) -> IEC 62443-4-2 - 1.1.2 CR RE | C4: =FR1_IAC!D17 -> 0 | D4: IEC62443-4-2 | E4: =E3 -> FR 1 - Identification and authentication control (IAC) | F4: 1.01 CR | G4: =IF(ISNUMBER(SEARCH(" ",M4)),CONCATENATE("RE(",RIGHT(N4),")"),"n/a") -> RE(2) | H4: =FR1_IAC!C15 -> Multifactor authentication for all interfaces | I4: =FR1_IAC!C16 -> Components shall provide the capability to employ multifactor authentication for all human user access to the component. | J4: =FR1_IAC!J17 -> 3 | K4: =FR1_IAC!D16 -> 0 | L4: IEC 62443-4-2 | M4: =FR1_IAC!A15 -> CR RE | N4: =FR1_IAC!B15 -> 1.1.2 | O4: No | P4: =IF(ISNUMBER(SEARCH(" ",M4)),CONCATENATE(MID(N4,1,LEN(N4)-2)," ",LEFT(M4,FIND(" ",M4)-1)),CONCATENATE(N4," ",M4)) -> 1.1 CR
A5: 4 | B5: =CONCATENATE(L5," - ",N5," ",M5) -> IEC 62443-4-2 - 1.2 CR | C5: =FR1_IAC!D20 -> 0 | D5: IEC62443-4-2 | E5: =E4 -> FR 1 - Identification and authentication control (IAC) | F5: 1.02 CR | G5: =IF(ISNUMBER(SEARCH(" ",M5)),CONCATENATE("RE(",RIGHT(N5),")"),"n/a") -> n/a | H5: =FR1_IAC!C18 -> Software process and device identification and authentication | I5: =FR1_IAC!C19 -> The component shall provide the capability to identify itself and authenticate to any other component (software application, embedded devices, host devices and network devices), according to ISA‑62443‑3‑3 SR1.2 If the component is running in the context of a human user, in addition, the identification and authentication of the human user according to ISA‑62443‑3‑3 SR1.1 may be part of the component identification and authentication process towards the other components. | J5: =FR1_IAC!J20 -> 2 | K5: =FR1_IAC!D19 -> 0 | L5: IEC 62443-4-2 | M5: =FR1_IAC!A18 -> CR | N5: =FR1_IAC!B18 -> 1.2 | O5: No | P5: =IF(ISNUMBER(SEARCH(" ",M5)),CONCATENATE(MID(N5,1,LEN(N5)-2)," ",LEFT(M5,FIND(" ",M5)-1)),CONCATENATE(N5," ",M5)) -> 1.2 CR
A6: 5 | B6: =CONCATENATE(L6," - ",N6," ",M6) -> IEC 62443-4-2 - 1.2.1 CR RE | C6: =FR1_IAC!D23 -> 0 | D6: IEC62443-4-2 | E6: =E5 -> FR 1 - Identification and authentication control (IAC) | F6: 1.02 CR | G6: =IF(ISNUMBER(SEARCH(" ",M6)),CONCATENATE("RE(",RIGHT(N6),")"),"n/a") -> RE(1) | H6: =FR1_IAC!C21 -> Unique identification and authentication | I6: =FR1_IAC!C22 -> The component shall provide the capability to uniquely identify and authenticate itself to any other component. | J6: =FR1_IAC!J23 -> 3 | K6: =FR1_IAC!D22 -> 0 | L6: IEC 62443-4-2 | M6: =FR1_IAC!A21 -> CR RE | N6: =FR1_IAC!B21 -> 1.2.1 | O6: No | P6: =IF(ISNUMBER(SEARCH(" ",M6)),CONCATENATE(MID(N6,1,LEN(N6)-2)," ",LEFT(M6,FIND(" ",M6)-1)),CONCATENATE(N6," ",M6)) -> 1.2 CR
A7: 6 | B7: =CONCATENATE(L7," - ",N7," ",M7) -> IEC 62443-4-2 - 1.3 CR | C7: =FR1_IAC!D26 -> Supported with some restrictions/partly needs clarifications | D7: IEC62443-4-2 | E7: =E6 -> FR 1 - Identification and authentication control (IAC) | F7: 1.03 CR | G7: =IF(ISNUMBER(SEARCH(" ",M7)),CONCATENATE("RE(",RIGHT(N7),")"),"n/a") -> n/a | H7: =FR1_IAC!C24 -> Account management | I7: =FR1_IAC!C25 -> Components shall provide the capability to support the management of all accounts directly or integrated into a system according to ISA‑62443‑3‑3 SR 1.3 | J7: =FR1_IAC!J26 -> 1 | K7: =FR1_IAC!D25 -> MCSR has a "not" requirement. Improvement would be to write it positive like in 62443: Products should have Account- and Authenticator Management, adding accounts is not an MCSR. Note: -3-3 requirement is "The control system shall provide the capability to support the management of all accounts by authorized users, including adding, activating, modifying, disabling and removing accounts." ABB Acceptance: FAQ: all accounts: also includes debug/maintenance accounts. FAQ: all accounts: also includes single admin account with changeable password. FAQ: if there is no account, then there is nothing to manage | L7: IEC 62443-4-2 | M7: =FR1_IAC!A24 -> CR | N7: =FR1_IAC!B24 -> 1.3 | O7: No | P7: =IF(ISNUMBER(SEARCH(" ",M7)),CONCATENATE(MID(N7,1,LEN(N7)-2)," ",LEFT(M7,FIND(" ",M7)-1)),CONCATENATE(N7," ",M7)) -> 1.3 CR
A8: 7 | B8: =CONCATENATE(L8," - ",N8," ",M8) -> IEC 62443-4-2 - 1.4 CR | C8: =FR1_IAC!D29 -> 0 | D8: IEC62443-4-2 | E8: =E7 -> FR 1 - Identification and authentication control (IAC) | F8: 1.04 CR | G8: =IF(ISNUMBER(SEARCH(" ",M8)),CONCATENATE("RE(",RIGHT(N8),")"),"n/a") -> n/a | H8: =FR1_IAC!C27 -> Identifier management | I8: =FR1_IAC!C28 -> The component shall provide the capability to integrate into a system that supports the management of identifiers and/or provide the capability to support the management of identifiers directly according to ISA‑62443‑3‑3 SR 1.4 | J8: =FR1_IAC!J29 -> 1 | K8: =FR1_IAC!D28 -> 0 | L8: IEC 62443-4-2 | M8: =FR1_IAC!A27 -> CR | N8: =FR1_IAC!B27 -> 1.4 | O8: No | P8: =IF(ISNUMBER(SEARCH(" ",M8)),CONCATENATE(MID(N8,1,LEN(N8)-2)," ",LEFT(M8,FIND(" ",M8)-1)),CONCATENATE(N8," ",M8)) -> 1.4 CR
A9: 8 | B9: =CONCATENATE(L9," - ",N9," ",M9) -> IEC 62443-4-2 - 1.5 CR | C9: =FR1_IAC!D35 -> Supported with some restrictions/partly needs clarifications | D9: IEC62443-4-2 | E9: =E8 -> FR 1 - Identification and authentication control (IAC) | F9: 1.05 CR | G9: =IF(ISNUMBER(SEARCH(" ",M9)),CONCATENATE("RE(",RIGHT(N9),")"),"n/a") -> n/a | H9: =FR1_IAC!C30 -> Authenticator management | I9: =FR1_IAC!C31 -> Components shall provide the capability to: a) support the use of initial authenticator content; | J9: =FR1_IAC!J35 -> 1 | K9: =FR1_IAC!D31 -> This seems to be equivalent to our requirement that all passwords, keys, etc. (authenticators) shall be changeable. | L9: IEC 62443-4-2 | M9: =FR1_IAC!A30 -> CR | N9: =FR1_IAC!B30 -> 1.5 | O9: No | P9: =IF(ISNUMBER(SEARCH(" ",M9)),CONCATENATE(MID(N9,1,LEN(N9)-2)," ",LEFT(M9,FIND(" ",M9)-1)),CONCATENATE(N9," ",M9)) -> 1.5 CR
A10: 9 | B10: =CONCATENATE(L10," - ",N10," ",M10) -> IEC 62443-4-2 - 1.5.1 CR RE | C10: =FR1_IAC!D38 -> 0 | D10: IEC62443-4-2 | E10: =E9 -> FR 1 - Identification and authentication control (IAC) | F10: 1.05 CR | G10: =IF(ISNUMBER(SEARCH(" ",M10)),CONCATENATE("RE(",RIGHT(N10),")"),"n/a") -> RE(1) | H10: =FR1_IAC!C36 -> Hardware security for authenticators | I10: =FR1_IAC!C37 -> The authenticators on which the component rely shall be protected via hardware mechanisms. Note: Examples of hardware authentication include: Password protected memory, OTP memory, hardware data integrity checks, and device security boot mechanism. | J10: =FR1_IAC!J38 -> 3 | K10: =FR1_IAC!D37 -> 0 | L10: IEC 62443-4-2 | M10: =FR1_IAC!A36 -> CR RE | N10: =FR1_IAC!B36 -> 1.5.1 | O10: No | P10: =IF(ISNUMBER(SEARCH(" ",M10)),CONCATENATE(MID(N10,1,LEN(N10)-2)," ",LEFT(M10,FIND(" ",M10)-1)),CONCATENATE(N10," ",M10)) -> 1.5 CR
A11: 10 | B11: =CONCATENATE(L11," - ",N11," ",M11) -> IEC 62443-4-2 - 1.6 NDR | C11: =FR1_IAC!D41 -> 0 | D11: IEC62443-4-2 | E11: =E10 -> FR 1 - Identification and authentication control (IAC) | F11: 1.06 NDR | G11: =IF(ISNUMBER(SEARCH(" ",M11)),CONCATENATE("RE(",RIGHT(N11),")"),"n/a") -> n/a | H11: =FR1_IAC!C39 -> Wireless access management | I11: =FR1_IAC!C40 -> A network device supporting wireless access management shall provide the capability to identify and authenticate all users (humans, software processes or devices) engaged in wireless communication. | J11: =FR1_IAC!J41 -> 1 | K11: =FR1_IAC!D40 -> MCSR MP-15 is focusing on application layer protocols, while wireless protocols typically act on lower layers (e.g. 802.11 on layer 2 and 1). | L11: IEC 62443-4-2 | M11: =FR1_IAC!A39 -> NDR | N11: =FR1_IAC!B39 -> 1.6 | O11: No | P11: =IF(ISNUMBER(SEARCH(" ",M11)),CONCATENATE(MID(N11,1,LEN(N11)-2)," ",LEFT(M11,FIND(" ",M11)-1)),CONCATENATE(N11," ",M11)) -> 1.6 NDR
A12: 11 | B12: =CONCATENATE(L12," - ",N12," ",M12) -> IEC 62443-4-2 - 1.6.1 NDR RE | C12: =FR1_IAC!D44 -> 0 | D12: IEC62443-4-2 | E12: =E11 -> FR 1 - Identification and authentication control (IAC) | F12: 1.06 NDR | G12: =IF(ISNUMBER(SEARCH(" ",M12)),CONCATENATE("RE(",RIGHT(N12),")"),"n/a") -> RE(1) | H12: =FR1_IAC!C42 -> Unique identification and authentication | I12: =FR1_IAC!C43 -> The network device shall provide the capability to uniquely identify and authenticate all users (humans, software processes or devices) engaged in wireless communication. | J12: =FR1_IAC!J44 -> 2 | K12: =FR1_IAC!D43 -> MCSR MP-15 is focusing on application layer protocols, while wireless protocols typically act on lower layers (e.g. 802.11 on layer 2 and 1). | L12: IEC 62443-4-2 | M12: =FR1_IAC!A42 -> NDR RE | N12: =FR1_IAC!B42 -> 1.6.1 | O12: No | P12: =IF(ISNUMBER(SEARCH(" ",M12)),CONCATENATE(MID(N12,1,LEN(N12)-2)," ",LEFT(M12,FIND(" ",M12)-1)),CONCATENATE(N12," ",M12)) -> 1.6 NDR
A13: 12 | B13: =CONCATENATE(L13," - ",N13," ",M13) -> IEC 62443-4-2 - 1.7 CR | C13: =FR1_IAC!D47 -> 0 | D13: IEC62443-4-2 | E13: =E12 -> FR 1 - Identification and authentication control (IAC) | F13: 1.07 CR | G13: =IF(ISNUMBER(SEARCH(" ",M13)),CONCATENATE("RE(",RIGHT(N13),")"),"n/a") -> n/a | H13: =FR1_IAC!C45 -> Strength of password-based authentication | I13: =FR1_IAC!C46 -> For components that utilize password-based authentication, those component shall provide or integrate into a system that provides the capability to enforce configurable password strength based on internationally recognized and proven password guidelines. | J13: =FR1_IAC!J47 -> 1 | K13: =FR1_IAC!D46 -> 0 | L13: IEC 62443-4-2 | M13: =FR1_IAC!A45 -> CR | N13: =FR1_IAC!B45 -> 1.7 | O13: No | P13: =IF(ISNUMBER(SEARCH(" ",M13)),CONCATENATE(MID(N13,1,LEN(N13)-2)," ",LEFT(M13,FIND(" ",M13)-1)),CONCATENATE(N13," ",M13)) -> 1.7 CR
A14: 13 | B14: =CONCATENATE(L14," - ",N14," ",M14) -> IEC 62443-4-2 - 1.7.1 CR RE | C14: =FR1_IAC!D50 -> 0 | D14: IEC62443-4-2 | E14: =E13 -> FR 1 - Identification and authentication control (IAC) | F14: 1.07 CR | G14: =IF(ISNUMBER(SEARCH(" ",M14)),CONCATENATE("RE(",RIGHT(N14),")"),"n/a") -> RE(1) | H14: =FR1_IAC!C48 -> Password generation and lifetime restrictions for human users | I14: =FR1_IAC!C49 -> Components shall provide, or integrate into a system that provides, the capability to protect against any given human user account from reusing a password for a configurable number of generations. In addition, the component shall provide the capability to enforce password minimum and maximum lifetime restrictions for human users. These capabilities shall conform to commonly accepted security industry practices. The component should provide the capability to prompt the user to change their password upon a configurable time prior to expiration. | J14: =FR1_IAC!J50 -> 3 | K14: =FR1_IAC!D49 -> 0 | L14: IEC 62443-4-2 | M14: =FR1_IAC!A48 -> CR RE | N14: =FR1_IAC!B48 -> 1.7.1 | O14: No | P14: =IF(ISNUMBER(SEARCH(" ",M14)),CONCATENATE(MID(N14,1,LEN(N14)-2)," ",LEFT(M14,FIND(" ",M14)-1)),CONCATENATE(N14," ",M14)) -> 1.7 CR
A15: 14 | B15: =CONCATENATE(L15," - ",N15," ",M15) -> IEC 62443-4-2 - 1.7.2 CR RE | C15: =FR1_IAC!D53 -> 0 | D15: IEC62443-4-2 | E15: =E14 -> FR 1 - Identification and authentication control (IAC) | F15: 1.07 CR | G15: =IF(ISNUMBER(SEARCH(" ",M15)),CONCATENATE("RE(",RIGHT(N15),")"),"n/a") -> RE(2) | H15: =FR1_IAC!C51 -> Password lifetime restrictions for all users (human, software process, or device) | I15: =FR1_IAC!C52 -> Components shall provide, or integrate into a system that provides, the capability to enforce password minimum and maximum lifetime restrictions for all users. | J15: =FR1_IAC!J53 -> 4 | K15: =FR1_IAC!D52 -> 0 | L15: IEC 62443-4-2 | M15: =FR1_IAC!A51 -> CR RE | N15: =FR1_IAC!B51 -> 1.7.2 | O15: No | P15: =IF(ISNUMBER(SEARCH(" ",M15)),CONCATENATE(MID(N15,1,LEN(N15)-2)," ",LEFT(M15,FIND(" ",M15)-1)),CONCATENATE(N15," ",M15)) -> 1.7 CR
A16: 15 | B16: =CONCATENATE(L16," - ",N16," ",M16) -> IEC 62443-4-2 - 1.8 CR | C16: =FR1_IAC!D56 -> 0 | D16: IEC62443-4-2 | E16: =E15 -> FR 1 - Identification and authentication control (IAC) | F16: 1.08 CR | G16: =IF(ISNUMBER(SEARCH(" ",M16)),CONCATENATE("RE(",RIGHT(N16),")"),"n/a") -> n/a | H16: =FR1_IAC!C54 -> Public key infrastructure certificates | I16: =FR1_IAC!C55 -> When public key infrastructure (PKI) is utilized, the component shall provide or integrate into a system that provides the capability to interact and operate in accordance with ISA‑62443‑3‑3 SR1.8 | J16: =FR1_IAC!J56 -> 2 | K16: =FR1_IAC!D55 -> 0 | L16: IEC 62443-4-2 | M16: =FR1_IAC!A54 -> CR | N16: =FR1_IAC!B54 -> 1.8 | O16: No | P16: =IF(ISNUMBER(SEARCH(" ",M16)),CONCATENATE(MID(N16,1,LEN(N16)-2)," ",LEFT(M16,FIND(" ",M16)-1)),CONCATENATE(N16," ",M16)) -> 1.8 CR
A17: 16 | B17: =CONCATENATE(L17," - ",N17," ",M17) -> IEC 62443-4-2 - 1.9 CR | C17: =FR1_IAC!D59 -> 0 | D17: IEC62443-4-2 | E17: =E16 -> FR 1 - Identification and authentication control (IAC) | F17: 1.09 CR | G17: =IF(ISNUMBER(SEARCH(" ",M17)),CONCATENATE("RE(",RIGHT(N17),")"),"n/a") -> n/a | H17: =FR1_IAC!C57 -> Strength of public key authentication | I17: =FR1_IAC!C58 -> For components that utilize public key authentication, those components shall provide directly or integrate into a system that provides the capability within the same IACS environment to: a) validate certificates by checking the validity of the signature of a given certificate; b) validate the certificate chain or, in the case of self-signed certificates, by deploying leaf certificates to all hosts that communicate with the subject to which the certificate is issued; c) validate certificates by checking a given certificate’s revocation status; d) establish user (human, software process or device) control of the corresponding private key; e) map the authenticated identity to a user (human, software process or device); and f) ensure that the algorithms and keys used for the symmetric key authentication comply with 8.5 CR 4.3 – Use of cryptography. | J17: =FR1_IAC!J59 -> 2 | K17: =FR1_IAC!D58 -> 0 | L17: IEC 62443-4-2 | M17: =FR1_IAC!A57 -> CR | N17: =FR1_IAC!B57 -> 1.9 | O17: No | P17: =IF(ISNUMBER(SEARCH(" ",M17)),CONCATENATE(MID(N17,1,LEN(N17)-2)," ",LEFT(M17,FIND(" ",M17)-1)),CONCATENATE(N17," ",M17)) -> 1.9 CR
A18: 17 | B18: =CONCATENATE(L18," - ",N18," ",M18) -> IEC 62443-4-2 - 1.9.1 CR RE | C18: =FR1_IAC!D62 -> 0 | D18: IEC62443-4-2 | E18: =E17 -> FR 1 - Identification and authentication control (IAC) | F18: 1.09 CR | G18: =IF(ISNUMBER(SEARCH(" ",M18)),CONCATENATE("RE(",RIGHT(N18),")"),"n/a") -> RE(1) | H18: =FR1_IAC!C60 -> Hardware security for public key authentication | I18: =FR1_IAC!C61 -> Hardware security for public key authentication Components shall provide the capability to protect critical, long-lived private keys via hardware mechanisms. | J18: =FR1_IAC!J62 -> 3 | K18: =FR1_IAC!D61 -> 0 | L18: IEC 62443-4-2 | M18: =FR1_IAC!A60 -> CR RE | N18: =FR1_IAC!B60 -> 1.9.1 | O18: No | P18: =IF(ISNUMBER(SEARCH(" ",M18)),CONCATENATE(MID(N18,1,LEN(N18)-2)," ",LEFT(M18,FIND(" ",M18)-1)),CONCATENATE(N18," ",M18)) -> 1.9 CR
A19: 18 | B19: =CONCATENATE(L19," - ",N19," ",M19) -> IEC 62443-4-2 - 1.10 CR | C19: =FR1_IAC!D65 -> 0 | D19: IEC62443-4-2 | E19: =E18 -> FR 1 - Identification and authentication control (IAC) | F19: 1.10 CR | G19: =IF(ISNUMBER(SEARCH(" ",M19)),CONCATENATE("RE(",RIGHT(N19),")"),"n/a") -> n/a | H19: =FR1_IAC!C63 -> Authenticator feedback | I19: =FR1_IAC!C64 -> When a component provides an authentication capability, the component shall provide the capability to obscure feedback of authentication information during the authentication process. | J19: =FR1_IAC!J65 -> 1 | K19: =FR1_IAC!D64 -> 0 | L19: IEC 62443-4-2 | M19: =FR1_IAC!A63 -> CR | N19: =FR1_IAC!B63 -> 1.10 | O19: No | P19: =IF(ISNUMBER(SEARCH(" ",M19)),CONCATENATE(MID(N19,1,LEN(N19)-2)," ",LEFT(M19,FIND(" ",M19)-1)),CONCATENATE(N19," ",M19)) -> 1.10 CR
A20: 19 | B20: =CONCATENATE(L20," - ",N20," ",M20) -> IEC 62443-4-2 - 1.11 CR | C20: =FR1_IAC!D68 -> 0 | D20: IEC62443-4-2 | E20: =E19 -> FR 1 - Identification and authentication control (IAC) | F20: 1.11 CR | G20: =IF(ISNUMBER(SEARCH(" ",M20)),CONCATENATE("RE(",RIGHT(N20),")"),"n/a") -> n/a | H20: =FR1_IAC!C66 -> Unsuccessful login attempts | I20: =FR1_IAC!C67 -> When a component provides an authentication capability, the component shall provide the capability to: a) enforce a limit of a configurable number of consecutive invalid access attempts by any user (human, software process or device) during a configurable time period; and b) deny access for a specified period of time or until unlocked by an administrator when this limit has been reached. An administrator may unlock an account prior to the expiration of the timeout period. | J20: =FR1_IAC!J68 -> 1 | K20: =FR1_IAC!D67 -> 0 | L20: IEC 62443-4-2 | M20: =FR1_IAC!A66 -> CR | N20: =FR1_IAC!B66 -> 1.11 | O20: No | P20: =IF(ISNUMBER(SEARCH(" ",M20)),CONCATENATE(MID(N20,1,LEN(N20)-2)," ",LEFT(M20,FIND(" ",M20)-1)),CONCATENATE(N20," ",M20)) -> 1.11 CR
A21: 20 | B21: =CONCATENATE(L21," - ",N21," ",M21) -> IEC 62443-4-2 - 1.12 CR | C21: =FR1_IAC!D71 -> 0 | D21: IEC62443-4-2 | E21: =E20 -> FR 1 - Identification and authentication control (IAC) | F21: 1.12 CR | G21: =IF(ISNUMBER(SEARCH(" ",M21)),CONCATENATE("RE(",RIGHT(N21),")"),"n/a") -> n/a | H21: =FR1_IAC!C69 -> System use notification | I21: =FR1_IAC!C70 -> When a component provides local human user access/HMI, it shall provide the capability to display a system use notification message before authenticating. The system use notification message shall be configurable by authorized personnel. | J21: =FR1_IAC!J71 -> 1 | K21: =FR1_IAC!D70 -> 0 | L21: IEC 62443-4-2 | M21: =FR1_IAC!A69 -> CR | N21: =FR1_IAC!B69 -> 1.12 | O21: No | P21: =IF(ISNUMBER(SEARCH(" ",M21)),CONCATENATE(MID(N21,1,LEN(N21)-2)," ",LEFT(M21,FIND(" ",M21)-1)),CONCATENATE(N21," ",M21)) -> 1.12 CR
A22: 21 | B22: =CONCATENATE(L22," - ",N22," ",M22) -> IEC 62443-4-2 - 1.13 NDR | C22: =FR1_IAC!D74 -> 0 | D22: IEC62443-4-2 | E22: =E21 -> FR 1 - Identification and authentication control (IAC) | F22: 1.13 NDR | G22: =IF(ISNUMBER(SEARCH(" ",M22)),CONCATENATE("RE(",RIGHT(N22),")"),"n/a") -> n/a | H22: =FR1_IAC!C72 -> Access via untrusted networks | I22: =FR1_IAC!C73 -> The network device supporting device access into a network shall provide the capability to monitor and control all methods of access to the network device via untrusted networks. | J22: =FR1_IAC!J74 -> 1 | K22: =FR1_IAC!D73 -> 0 | L22: IEC 62443-4-2 | M22: =FR1_IAC!A72 -> NDR | N22: =FR1_IAC!B72 -> 1.13 | O22: No | P22: =IF(ISNUMBER(SEARCH(" ",M22)),CONCATENATE(MID(N22,1,LEN(N22)-2)," ",LEFT(M22,FIND(" ",M22)-1)),CONCATENATE(N22," ",M22)) -> 1.13 NDR
A23: 22 | B23: =CONCATENATE(L23," - ",N23," ",M23) -> IEC 62443-4-2 - 1.13.1 NDR RE | C23: =FR1_IAC!D77 -> 0 | D23: IEC62443-4-2 | E23: =E22 -> FR 1 - Identification and authentication control (IAC) | F23: 1.13 NDR | G23: =IF(ISNUMBER(SEARCH(" ",M23)),CONCATENATE("RE(",RIGHT(N23),")"),"n/a") -> RE(1) | H23: =FR1_IAC!C75 -> Explicity access request approval | I23: =FR1_IAC!C76 -> The network device shall provide the capability to deny access requests via untrusted networks unless explicitly approved by an assigned role. | J23: =FR1_IAC!J77 -> 3 | K23: =FR1_IAC!D76 -> 0 | L23: IEC 62443-4-2 | M23: =FR1_IAC!A75 -> NDR RE | N23: =FR1_IAC!B75 -> 1.13.1 | O23: No | P23: =IF(ISNUMBER(SEARCH(" ",M23)),CONCATENATE(MID(N23,1,LEN(N23)-2)," ",LEFT(M23,FIND(" ",M23)-1)),CONCATENATE(N23," ",M23)) -> 1.13 NDR
A24: 23 | B24: =CONCATENATE(L24," - ",N24," ",M24) -> IEC 62443-4-2 - 1.14 CR | C24: =FR1_IAC!D80 -> 0 | D24: IEC62443-4-2 | E24: =E23 -> FR 1 - Identification and authentication control (IAC) | F24: 1.14 CR | G24: =IF(ISNUMBER(SEARCH(" ",M24)),CONCATENATE("RE(",RIGHT(N24),")"),"n/a") -> n/a | H24: =FR1_IAC!C78 -> Strength of symmetric key authentication | I24: =FR1_IAC!C79 -> For components that utilize symmetric keys, the component shall provide the capability to: a) establish the mutual trust using the symmetric key; b) store securely the shared secret (the authentication is valid as long as the shared secret remains secret); c) restrict access to the shared secret; and d) ensure that the algorithms and keys used for the symmetric key authentication comply with CR 4.3 – Use of cryptography. | J24: =FR1_IAC!J80 -> 2 | K24: =FR1_IAC!D79 -> 0 | L24: IEC 62443-4-2 | M24: =FR1_IAC!A78 -> CR | N24: =FR1_IAC!B78 -> 1.14 | O24: No | P24: =IF(ISNUMBER(SEARCH(" ",M24)),CONCATENATE(MID(N24,1,LEN(N24)-2)," ",LEFT(M24,FIND(" ",M24)-1)),CONCATENATE(N24," ",M24)) -> 1.14 CR
A25: 24 | B25: =CONCATENATE(L25," - ",N25," ",M25) -> IEC 62443-4-2 - 1.14.1 CR RE | C25: =FR1_IAC!D83 -> 0 | D25: IEC62443-4-2 | E25: =E24 -> FR 1 - Identification and authentication control (IAC) | F25: 1.14 CR | G25: =IF(ISNUMBER(SEARCH(" ",M25)),CONCATENATE("RE(",RIGHT(N25),")"),"n/a") -> RE(1) | H25: =FR1_IAC!C81 -> Hardware security for symmetric key-based authentication | I25: =FR1_IAC!C82 -> Components shall provide the capability to protect critical, long lived symmetric keys via hardware mechanisms. | J25: =FR1_IAC!J83 -> 3 | K25: =FR1_IAC!D82 -> 0 | L25: IEC 62443-4-2 | M25: =FR1_IAC!A81 -> CR RE | N25: =FR1_IAC!B81 -> 1.14.1 | O25: No | P25: =IF(ISNUMBER(SEARCH(" ",M25)),CONCATENATE(MID(N25,1,LEN(N25)-2)," ",LEFT(M25,FIND(" ",M25)-1)),CONCATENATE(N25," ",M25)) -> 1.14 CR
A26: 25 | B26: =CONCATENATE(L26," - ",N26," ",M26) -> IEC 62443-4-2 - 2.1 CR | C26: =FR2_UC!D11 -> 0 | D26: IEC62443-4-2 | E26: =FR2_UC!A$7 -> FR 2 - Use Control (UC) | F26: 2.01 CR | G26: =IF(ISNUMBER(SEARCH(" ",M26)),CONCATENATE("RE(",RIGHT(N26),")"),"n/a") -> n/a | H26: =FR2_UC!C9 -> Authorization enforcement | I26: =FR2_UC!C10 -> The component shall provide an authorization enforcement mechanism for all identified and authenticated human users based on their assigned responsibilities. | J26: =FR2_UC!J11 -> 1 | K26: =FR2_UC!D10 -> 0 | L26: IEC 62443-4-2 | M26: =FR2_UC!A9 -> CR | N26: =FR2_UC!B9 -> 2.1 | O26: No | P26: =IF(ISNUMBER(SEARCH(" ",M26)),CONCATENATE(MID(N26,1,LEN(N26)-2)," ",LEFT(M26,FIND(" ",M26)-1)),CONCATENATE(N26," ",M26)) -> 2.1 CR
A27: 26 | B27: =CONCATENATE(L27," - ",N27," ",M27) -> IEC 62443-4-2 - 2.1.1 CR RE | C27: =FR2_UC!D14 -> 0 | D27: IEC62443-4-2 | E27: =E26 -> FR 2 - Use Control (UC) | F27: 2.01 CR | G27: =IF(ISNUMBER(SEARCH(" ",M27)),CONCATENATE("RE(",RIGHT(N27),")"),"n/a") -> RE(1) | H27: =FR2_UC!C12 -> Authorization enforcement for all users (humans, software processes and devices) | I27: =FR2_UC!C13 -> Components shall provide an authorization enforcement mechanism for all users based on their assigned responsibilities and least privilege. | J27: =FR2_UC!J14 -> 2 | K27: =FR2_UC!D13 -> 0 | L27: IEC 62443-4-2 | M27: =FR2_UC!A12 -> CR RE | N27: =FR2_UC!B12 -> 2.1.1 | O27: No | P27: =IF(ISNUMBER(SEARCH(" ",M27)),CONCATENATE(MID(N27,1,LEN(N27)-2)," ",LEFT(M27,FIND(" ",M27)-1)),CONCATENATE(N27," ",M27)) -> 2.1 CR
A28: 27 | B28: =CONCATENATE(L28," - ",N28," ",M28) -> IEC 62443-4-2 - 2.1.2 CR RE | C28: =FR2_UC!D17 -> 0 | D28: IEC62443-4-2 | E28: =E27 -> FR 2 - Use Control (UC) | F28: 2.01 CR | G28: =IF(ISNUMBER(SEARCH(" ",M28)),CONCATENATE("RE(",RIGHT(N28),")"),"n/a") -> RE(2) | H28: =FR2_UC!C15 -> Permission mapping to roles | I28: =FR2_UC!C16 -> Components shall, directly or through a compensating security mechanism, provide for an authorized role to define and modify the mapping of permissions to roles for all human users. Roles should not be limited to fixed nested hierarchies in which a higher-level role is a super set of a lesser privileged role. For example, a system administrator should not necessarily encompass operator privileges. NOTE 1 This RE is applicable to software processes and devices as well. | J28: =FR2_UC!J17 -> 2 | K28: =FR2_UC!D16 -> 0 | L28: IEC 62443-4-2 | M28: =FR2_UC!A15 -> CR RE | N28: =FR2_UC!B15 -> 2.1.2 | O28: No | P28: =IF(ISNUMBER(SEARCH(" ",M28)),CONCATENATE(MID(N28,1,LEN(N28)-2)," ",LEFT(M28,FIND(" ",M28)-1)),CONCATENATE(N28," ",M28)) -> 2.1 CR
A29: 28 | B29: =CONCATENATE(L29," - ",N29," ",M29) -> IEC 62443-4-2 - 2.1.3 CR RE | C29: =FR2_UC!D20 -> 0 | D29: IEC62443-4-2 | E29: =E28 -> FR 2 - Use Control (UC) | F29: 2.01 CR | G29: =IF(ISNUMBER(SEARCH(" ",M29)),CONCATENATE("RE(",RIGHT(N29),")"),"n/a") -> RE(3) | H29: =FR2_UC!C18 -> Supervisor override | I29: =FR2_UC!C19 -> Components shall support a supervisor manual override for a configurable time or sequence of events. NOTE 2 Implementation of a controlled, audited and manual override of automated mechanisms in the event of emergencies or other serious events is often needed. This allows a supervisor to enable an operator to quickly react to unusual conditions without closing the current session and establishing a new session as a higher privilege human user. | J29: =FR2_UC!J20 -> 3 | K29: =FR2_UC!D19 -> 0 | L29: IEC 62443-4-2 | M29: =FR2_UC!A18 -> CR RE | N29: =FR2_UC!B18 -> 2.1.3 | O29: No | P29: =IF(ISNUMBER(SEARCH(" ",M29)),CONCATENATE(MID(N29,1,LEN(N29)-2)," ",LEFT(M29,FIND(" ",M29)-1)),CONCATENATE(N29," ",M29)) -> 2.1 CR
A30: 29 | B30: =CONCATENATE(L30," - ",N30," ",M30) -> IEC 62443-4-2 - 2.1.4 CR RE | C30: =FR2_UC!D23 -> 0 | D30: IEC62443-4-2 | E30: =E29 -> FR 2 - Use Control (UC) | F30: 2.01 CR | G30: =IF(ISNUMBER(SEARCH(" ",M30)),CONCATENATE("RE(",RIGHT(N30),")"),"n/a") -> RE(4) | H30: =FR2_UC!C21 -> Dual approval | I30: =FR2_UC!C22 -> Components shall support dual approval when action can result in serious impact on the industrial process. Dual approval should be limited to actions which require a very high level of confidence that they will be performed reliably and correctly. Requiring dual approval provides emphasis to the seriousness of consequences that would result from failure of a correct action. An example of a situation in which dual approval is required would be a change to a set point of a critical industrial process. Dual approval mechanisms should not be employed when an immediate response is necessary to safeguard HSE consequences, for example, emergency shutdown of an industrial process. | J30: =FR2_UC!J23 -> 4 | K30: =FR2_UC!D22 -> 0 | L30: IEC 62443-4-2 | M30: =FR2_UC!A21 -> CR RE | N30: =FR2_UC!B21 -> 2.1.4 | O30: No | P30: =IF(ISNUMBER(SEARCH(" ",M30)),CONCATENATE(MID(N30,1,LEN(N30)-2)," ",LEFT(M30,FIND(" ",M30)-1)),CONCATENATE(N30," ",M30)) -> 2.1 CR
A31: 30 | B31: =CONCATENATE(L31," - ",N31," ",M31) -> IEC 62443-4-2 - 2.2 CR | C31: =FR2_UC!D26 -> 0 | D31: IEC62443-4-2 | E31: =E30 -> FR 2 - Use Control (UC) | F31: 2.02 CR | G31: =IF(ISNUMBER(SEARCH(" ",M31)),CONCATENATE("RE(",RIGHT(N31),")"),"n/a") -> n/a | H31: =FR2_UC!C24 -> Wireless use control | I31: =FR2_UC!C25 -> If a component supports usage through wireless interfaces it shall provide the capability to authorize, monitor and enforce usage restrictions according to commonly accepted industry practices. | J31: =FR2_UC!J26 -> 1 | K31: =FR2_UC!D25 -> 0 | L31: IEC 62443-4-2 | M31: =FR2_UC!A24 -> CR | N31: =FR2_UC!B24 -> 2.2 | O31: No | P31: =IF(ISNUMBER(SEARCH(" ",M31)),CONCATENATE(MID(N31,1,LEN(N31)-2)," ",LEFT(M31,FIND(" ",M31)-1)),CONCATENATE(N31," ",M31)) -> 2.2 CR
A32: 31 | B32: =CONCATENATE(L32," - ",N32," ",M32) -> IEC 62443-4-2 - 2.3 CR | C32: =FR2_UC!D29 -> 0 | D32: IEC62443-4-2 | E32: =E31 -> FR 2 - Use Control (UC) | F32: 2.03 CR | G32: =IF(ISNUMBER(SEARCH(" ",M32)),CONCATENATE("RE(",RIGHT(N32),")"),"n/a") -> n/a | H32: =FR2_UC!C27 -> Use control for portable and mobile devices | I32: =FR2_UC!C28 -> There is no component level requirement associated with ISA‑62443‑3‑3 SR 2.3. | J32: =FR2_UC!J29 -> 0 | K32: =FR2_UC!D28 -> 0 | L32: IEC 62443-4-2 | M32: =FR2_UC!A27 -> CR | N32: =FR2_UC!B27 -> 2.3 | O32: No | P32: =IF(ISNUMBER(SEARCH(" ",M32)),CONCATENATE(MID(N32,1,LEN(N32)-2)," ",LEFT(M32,FIND(" ",M32)-1)),CONCATENATE(N32," ",M32)) -> 2.3 CR
A33: 32 | B33: =CONCATENATE(L33," - ",N33," ",M33) -> IEC 62443-4-2 - 2.4 SAR | C33: =FR2_UC!D32 -> 0 | D33: IEC62443-4-2 | E33: =E32 -> FR 2 - Use Control (UC) | F33: 2.04 SAR | G33: =IF(ISNUMBER(SEARCH(" ",M33)),CONCATENATE("RE(",RIGHT(N33),")"),"n/a") -> n/a | H33: =FR2_UC!C30 -> Mobile code | I33: =FR2_UC!C31 -> In the event that a software application utilizes mobile code technologies, that application shall provide the capability to enforce a security policy for the usage of mobile code technologies. The security policy shall allow, at a minimum, the following actions for each mobile code technology used on the software application: a) Control execution of mobile code; b) Control which users (human, software process, or device) are allowed to transfer mobile code to/from the application; c) Control the execution of mobile code based on the results of an integrity check prior to the code being executed. | J33: =FR2_UC!J32 -> 1 | K33: =FR2_UC!D31 -> 0 | L33: IEC 62443-4-2 | M33: =FR2_UC!A30 -> SAR | N33: =FR2_UC!B30 -> 2.4 | O33: No | P33: =IF(ISNUMBER(SEARCH(" ",M33)),CONCATENATE(MID(N33,1,LEN(N33)-2)," ",LEFT(M33,FIND(" ",M33)-1)),CONCATENATE(N33," ",M33)) -> 2.4 SAR
A34: 33 | B34: =CONCATENATE(L34," - ",N34," ",M34) -> IEC 62443-4-2 - 2.4.1 SAR RE | C34: =FR2_UC!D35 -> 0 | D34: IEC62443-4-2 | E34: =E33 -> FR 2 - Use Control (UC) | F34: 2.04 SAR | G34: =IF(ISNUMBER(SEARCH(" ",M34)),CONCATENATE("RE(",RIGHT(N34),")"),"n/a") -> RE(1) | H34: =FR2_UC!C33 -> Mobile code authenticity check | I34: =FR2_UC!C34 -> The application shall provide the capability to enforce a security policy that allows the device to control execution of mobile code based on the results of an authenticity check prior to the code being executed. | J34: =FR2_UC!J35 -> 2 | K34: =FR2_UC!D34 -> 0 | L34: IEC 62443-4-2 | M34: =FR2_UC!A33 -> SAR RE | N34: =FR2_UC!B33 -> 2.4.1 | O34: No | P34: =IF(ISNUMBER(SEARCH(" ",M34)),CONCATENATE(MID(N34,1,LEN(N34)-2)," ",LEFT(M34,FIND(" ",M34)-1)),CONCATENATE(N34," ",M34)) -> 2.4 SAR
A35: 34 | B35: =CONCATENATE(L35," - ",N35," ",M35) -> IEC 62443-4-2 - 2.4 EDR | C35: =FR2_UC!D40 -> Supported with some restrictions/partly needs clarifications | D35: IEC62443-4-2 | E35: =E34 -> FR 2 - Use Control (UC) | F35: 2.04 EDR | G35: =IF(ISNUMBER(SEARCH(" ",M35)),CONCATENATE("RE(",RIGHT(N35),")"),"n/a") -> n/a | H35: =FR2_UC!C36 -> Mobile code | I35: =FR2_UC!C37 -> In the event that an embedded device utilizes mobile code technologies, the embedded device shall provide the capability to enforce a security policy for the usage of mobile code technologies. The security policy shall allow, at a minimum, the following actions for each mobile code technology used on the embedded device: a) Control execution of mobile code; | J35: =FR2_UC!J40 -> 1 | K35: =FR2_UC!D37 -> MCSR MP-5.1 is concentrating on Windows Malware scanning. This EDR 2.4 is more appropriate for Embedded devices. Definition from 62443: 3.1.29 mobile code program transferred between assets that can be executed without explicit installation by the recipient EXAMPLE JavaScript, VBScript, Java applets, ActiveX controls, Flash animations, Shockwave movies, and Microsoft Office macros. | L35: IEC 62443-4-2 | M35: =FR2_UC!A36 -> EDR | N35: =FR2_UC!B36 -> 2.4 | O35: No | P35: =IF(ISNUMBER(SEARCH(" ",M35)),CONCATENATE(MID(N35,1,LEN(N35)-2)," ",LEFT(M35,FIND(" ",M35)-1)),CONCATENATE(N35," ",M35)) -> 2.4 EDR
A36: 35 | B36: =CONCATENATE(L36," - ",N36," ",M36) -> IEC 62443-4-2 - 2.4.1 EDR RE | C36: =FR2_UC!D43 -> Supported with some restrictions/partly needs clarifications | D36: IEC62443-4-2 | E36: =E35 -> FR 2 - Use Control (UC) | F36: 2.04 EDR | G36: =IF(ISNUMBER(SEARCH(" ",M36)),CONCATENATE("RE(",RIGHT(N36),")"),"n/a") -> RE(1) | H36: =FR2_UC!C41 -> Mobile code authenticity check | I36: =FR2_UC!C42 -> The embedded device shall provide the capability to enforce a security policy that allows the device to control execution of mobile code based on the results of an authenticity check prior to the code being executed | J36: =FR2_UC!J43 -> 2 | K36: =FR2_UC!D42 -> 0 | L36: IEC 62443-4-2 | M36: =FR2_UC!A41 -> EDR RE | N36: =FR2_UC!B41 -> 2.4.1 | O36: No | P36: =IF(ISNUMBER(SEARCH(" ",M36)),CONCATENATE(MID(N36,1,LEN(N36)-2)," ",LEFT(M36,FIND(" ",M36)-1)),CONCATENATE(N36," ",M36)) -> 2.4 EDR
A37: 36 | B37: =CONCATENATE(L37," - ",N37," ",M37) -> IEC 62443-4-2 - 2.4 HDR | C37: =FR2_UC!D46 -> 0 | D37: IEC62443-4-2 | E37: =E36 -> FR 2 - Use Control (UC) | F37: 2.04 HDR | G37: =IF(ISNUMBER(SEARCH(" ",M37)),CONCATENATE("RE(",RIGHT(N37),")"),"n/a") -> n/a | H37: =FR2_UC!C44 -> Mobile code | I37: =FR2_UC!C45 -> In the event that a host device utilizes mobile code technologies, the embedded device shall provide the capability to enforce a security policy for the usage of mobile code technologies. The security policy shall allow, at a minimum, the following actions for each mobile code technology used on the host device: a) Control execution of mobile code; b) Control which users (human, software process, or device) are allowed to upload mobile code to the device; c) Control the code execution based upon integrity checks on the mobile code and prior to the code being executed | J37: =FR2_UC!J46 -> 1 | K37: =FR2_UC!D45 -> 0 | L37: IEC 62443-4-2 | M37: =FR2_UC!A44 -> HDR | N37: =FR2_UC!B44 -> 2.4 | O37: No | P37: =IF(ISNUMBER(SEARCH(" ",M37)),CONCATENATE(MID(N37,1,LEN(N37)-2)," ",LEFT(M37,FIND(" ",M37)-1)),CONCATENATE(N37," ",M37)) -> 2.4 HDR
A38: 37 | B38: =CONCATENATE(L38," - ",N38," ",M38) -> IEC 62443-4-2 - 2.4.1 HDR RE | C38: =FR2_UC!D49 -> 0 | D38: IEC62443-4-2 | E38: =E37 -> FR 2 - Use Control (UC) | F38: 2.04 HDR | G38: =IF(ISNUMBER(SEARCH(" ",M38)),CONCATENATE("RE(",RIGHT(N38),")"),"n/a") -> RE(1) | H38: =FR2_UC!C47 -> Mobile code authenticity check | I38: =FR2_UC!C48 -> The host device shall provide the capability to enforce a security policy that allows the device to control execution of mobile code based on the results of an authenticity check prior to the code being executed | J38: =FR2_UC!J49 -> 2 | K38: =FR2_UC!D48 -> 0 | L38: IEC 62443-4-2 | M38: =FR2_UC!A47 -> HDR RE | N38: =FR2_UC!B47 -> 2.4.1 | O38: No | P38: =IF(ISNUMBER(SEARCH(" ",M38)),CONCATENATE(MID(N38,1,LEN(N38)-2)," ",LEFT(M38,FIND(" ",M38)-1)),CONCATENATE(N38," ",M38)) -> 2.4 HDR
A39: 38 | B39: =CONCATENATE(L39," - ",N39," ",M39) -> IEC 62443-4-2 - 2.4 NDR | C39: =FR2_UC!D52 -> 0 | D39: IEC62443-4-2 | E39: =E38 -> FR 2 - Use Control (UC) | F39: 2.04 NDR | G39: =IF(ISNUMBER(SEARCH(" ",M39)),CONCATENATE("RE(",RIGHT(N39),")"),"n/a") -> n/a | H39: =FR2_UC!C50 -> Mobile code | I39: =FR2_UC!C51 -> In the event that a network device utilizes mobile code technologies, the embedded device shall provide the capability to enforce a security policy for the usage of mobile code technologies. The security policy shall allow, at a minimum, the following actions for each mobile code technology used on the network device: a) Control execution of mobile code; b) Control which users (human, software process, or device) are allowed to upload mobile code to the device; c) Control the code execution based upon integrity checks on the mobile code and prior to the code being executed | J39: =FR2_UC!J52 -> 1 | K39: =FR2_UC!D51 -> 0 | L39: IEC 62443-4-2 | M39: =FR2_UC!A50 -> NDR | N39: =FR2_UC!B50 -> 2.4 | O39: No | P39: =IF(ISNUMBER(SEARCH(" ",M39)),CONCATENATE(MID(N39,1,LEN(N39)-2)," ",LEFT(M39,FIND(" ",M39)-1)),CONCATENATE(N39," ",M39)) -> 2.4 NDR
A40: 39 | B40: =CONCATENATE(L40," - ",N40," ",M40) -> IEC 62443-4-2 - 2.4.1 NDR RE | C40: =FR2_UC!D55 -> 0 | D40: IEC62443-4-2 | E40: =E39 -> FR 2 - Use Control (UC) | F40: 2.04 NDR | G40: =IF(ISNUMBER(SEARCH(" ",M40)),CONCATENATE("RE(",RIGHT(N40),")"),"n/a") -> RE(1) | H40: =FR2_UC!C53 -> Mobile code authenticity check | I40: =FR2_UC!C54 -> The host device shall provide the capability to enforce a security policy that allows the device to control execution of mobile code based on the results of an authenticity check prior to the code being executed | J40: =FR2_UC!J55 -> 2 | K40: =FR2_UC!D54 -> 0 | L40: IEC 62443-4-2 | M40: =FR2_UC!A53 -> NDR RE | N40: =FR2_UC!B53 -> 2.4.1 | O40: No | P40: =IF(ISNUMBER(SEARCH(" ",M40)),CONCATENATE(MID(N40,1,LEN(N40)-2)," ",LEFT(M40,FIND(" ",M40)-1)),CONCATENATE(N40," ",M40)) -> 2.4 NDR
...

Sheet Summary
A1: ID | B1: Title | C1: Rating | D1: Comments | E1: Reference | F1: Standard | G1: Req.1 | H1: Req.2 | I1: References | J1: Comment | K1: Ref. Status | L1: SL-C
A2: 1 | B2: =CONCATENATE(F2," - ",H2," ",G2) -> IEC 62443-4-2 - 1.1 CR | C2: =FR1_IAC!D11 -> 0 | D2: =FR1_IAC!D10 -> 0 | F2: IEC 62443-4-2 | G2: =FR1_IAC!A9 -> CR | H2: =FR1_IAC!B9 -> 1.1 | I2: No | L2: =FR1_IAC!J11 -> 1
A3: 2 | B3: =CONCATENATE(F3," - ",H3," ",G3) -> IEC 62443-4-2 - 1.1.1 CR RE | C3: =FR1_IAC!D14 -> 0 | D3: =FR1_IAC!D13 -> 0 | F3: IEC 62443-4-2 | G3: =FR1_IAC!A12 -> CR RE | H3: =FR1_IAC!B12 -> 1.1.1 | I3: No | L3: =FR1_IAC!J14 -> 2
A4: 3 | B4: =CONCATENATE(F4," - ",H4," ",G4) -> IEC 62443-4-2 - 1.1.2 CR RE | C4: =FR1_IAC!D17 -> 0 | D4: =FR1_IAC!D16 -> 0 | F4: IEC 62443-4-2 | G4: =FR1_IAC!A15 -> CR RE | H4: =FR1_IAC!B15 -> 1.1.2 | I4: No | L4: =FR1_IAC!J17 -> 3
A5: 4 | B5: =CONCATENATE(F5," - ",H5," ",G5) -> IEC 62443-4-2 - 1.2 CR | C5: =FR1_IAC!D20 -> 0 | D5: =FR1_IAC!D19 -> 0 | F5: IEC 62443-4-2 | G5: =FR1_IAC!A18 -> CR | H5: =FR1_IAC!B18 -> 1.2 | I5: No | L5: =FR1_IAC!J20 -> 2
A6: 5 | B6: =CONCATENATE(F6," - ",H6," ",G6) -> IEC 62443-4-2 - 1.2.1 CR RE | C6: =FR1_IAC!D23 -> 0 | D6: =FR1_IAC!D22 -> 0 | F6: IEC 62443-4-2 | G6: =FR1_IAC!A21 -> CR RE | H6: =FR1_IAC!B21 -> 1.2.1 | I6: No | L6: =FR1_IAC!J23 -> 3
A7: 6 | B7: =CONCATENATE(F7," - ",H7," ",G7) -> IEC 62443-4-2 - 1.3 CR | C7: =FR1_IAC!D26 -> Supported with some restrictions/partly needs clarifications | D7: =FR1_IAC!D25 -> MCSR has a "not" requirement. Improvement would be to write it positive like in 62443: Products should have Account- and Authenticator Management, adding accounts is not an MCSR. Note: -3-3 requirement is "The control system shall provide the capability to support the management of all accounts by authorized users, including adding, activating, modifying, disabling and removing accounts." ABB Acceptance: FAQ: all accounts: also includes debug/maintenance accounts. FAQ: all accounts: also includes single admin account with changeable password. FAQ: if there is no account, then there is nothing to manage | F7: IEC 62443-4-2 | G7: =FR1_IAC!A24 -> CR | H7: =FR1_IAC!B24 -> 1.3 | I7: No | L7: =FR1_IAC!J26 -> 1
A8: 7 | B8: =CONCATENATE(F8," - ",H8," ",G8) -> IEC 62443-4-2 - 1.4 CR | C8: =FR1_IAC!D29 -> 0 | D8: =FR1_IAC!D28 -> 0 | F8: IEC 62443-4-2 | G8: =FR1_IAC!A27 -> CR | H8: =FR1_IAC!B27 -> 1.4 | I8: No | L8: =FR1_IAC!J29 -> 1
A9: 8 | B9: =CONCATENATE(F9," - ",H9," ",G9) -> IEC 62443-4-2 - 1.5 CR | C9: =FR1_IAC!D35 -> Supported with some restrictions/partly needs clarifications | D9: =FR1_IAC!D31 -> This seems to be equivalent to our requirement that all passwords, keys, etc. (authenticators) shall be changeable. | F9: IEC 62443-4-2 | G9: =FR1_IAC!A30 -> CR | H9: =FR1_IAC!B30 -> 1.5 | I9: No | L9: =FR1_IAC!J35 -> 1
A10: 9 | B10: =CONCATENATE(F10," - ",H10," ",G10) -> IEC 62443-4-2 - 1.5.1 CR RE | C10: =FR1_IAC!D38 -> 0 | D10: =FR1_IAC!D37 -> 0 | F10: IEC 62443-4-2 | G10: =FR1_IAC!A36 -> CR RE | H10: =FR1_IAC!B36 -> 1.5.1 | I10: No | L10: =FR1_IAC!J38 -> 3
A11: 10 | B11: =CONCATENATE(F11," - ",H11," ",G11) -> IEC 62443-4-2 - 1.6 NDR | C11: =FR1_IAC!D41 -> 0 | D11: =FR1_IAC!D40 -> MCSR MP-15 is focusing on application layer protocols, while wireless protocols typically act on lower layers (e.g. 802.11 on layer 2 and 1). | F11: IEC 62443-4-2 | G11: =FR1_IAC!A39 -> NDR | H11: =FR1_IAC!B39 -> 1.6 | I11: No | L11: =FR1_IAC!J41 -> 1
A12: 11 | B12: =CONCATENATE(F12," - ",H12," ",G12) -> IEC 62443-4-2 - 1.6.1 NDR RE | C12: =FR1_IAC!D44 -> 0 | D12: =FR1_IAC!D43 -> MCSR MP-15 is focusing on application layer protocols, while wireless protocols typically act on lower layers (e.g. 802.11 on layer 2 and 1). | F12: IEC 62443-4-2 | G12: =FR1_IAC!A42 -> NDR RE | H12: =FR1_IAC!B42 -> 1.6.1 | I12: No | L12: =FR1_IAC!J44 -> 2
A13: 12 | B13: =CONCATENATE(F13," - ",H13," ",G13) -> IEC 62443-4-2 - 1.7 CR | C13: =FR1_IAC!D47 -> 0 | D13: =FR1_IAC!D46 -> 0 | F13: IEC 62443-4-2 | G13: =FR1_IAC!A45 -> CR | H13: =FR1_IAC!B45 -> 1.7 | I13: No | L13: =FR1_IAC!J47 -> 1
A14: 13 | B14: =CONCATENATE(F14," - ",H14," ",G14) -> IEC 62443-4-2 - 1.7.1 CR RE | C14: =FR1_IAC!D50 -> 0 | D14: =FR1_IAC!D49 -> 0 | F14: IEC 62443-4-2 | G14: =FR1_IAC!A48 -> CR RE | H14: =FR1_IAC!B48 -> 1.7.1 | I14: No | L14: =FR1_IAC!J50 -> 3
A15: 14 | B15: =CONCATENATE(F15," - ",H15," ",G15) -> IEC 62443-4-2 - 1.7.2 CR RE | C15: =FR1_IAC!D53 -> 0 | D15: =FR1_IAC!D52 -> 0 | F15: IEC 62443-4-2 | G15: =FR1_IAC!A51 -> CR RE | H15: =FR1_IAC!B51 -> 1.7.2 | I15: No | L15: =FR1_IAC!J53 -> 4
A16: 15 | B16: =CONCATENATE(F16," - ",H16," ",G16) -> IEC 62443-4-2 - 1.8 CR | C16: =FR1_IAC!D56 -> 0 | D16: =FR1_IAC!D55 -> 0 | F16: IEC 62443-4-2 | G16: =FR1_IAC!A54 -> CR | H16: =FR1_IAC!B54 -> 1.8 | I16: No | L16: =FR1_IAC!J56 -> 2
A17: 16 | B17: =CONCATENATE(F17," - ",H17," ",G17) -> IEC 62443-4-2 - 1.9 CR | C17: =FR1_IAC!D59 -> 0 | D17: =FR1_IAC!D58 -> 0 | F17: IEC 62443-4-2 | G17: =FR1_IAC!A57 -> CR | H17: =FR1_IAC!B57 -> 1.9 | I17: No | L17: =FR1_IAC!J59 -> 2
A18: 17 | B18: =CONCATENATE(F18," - ",H18," ",G18) -> IEC 62443-4-2 - 1.9.1 CR RE | C18: =FR1_IAC!D62 -> 0 | D18: =FR1_IAC!D61 -> 0 | F18: IEC 62443-4-2 | G18: =FR1_IAC!A60 -> CR RE | H18: =FR1_IAC!B60 -> 1.9.1 | I18: No | L18: =FR1_IAC!J62 -> 3
A19: 18 | B19: =CONCATENATE(F19," - ",H19," ",G19) -> IEC 62443-4-2 - 1.10 CR | C19: =FR1_IAC!D65 -> 0 | D19: =FR1_IAC!D64 -> 0 | F19: IEC 62443-4-2 | G19: =FR1_IAC!A63 -> CR | H19: =FR1_IAC!B63 -> 1.10 | I19: No | L19: =FR1_IAC!J65 -> 1
A20: 19 | B20: =CONCATENATE(F20," - ",H20," ",G20) -> IEC 62443-4-2 - 1.11 CR | C20: =FR1_IAC!D68 -> 0 | D20: =FR1_IAC!D67 -> 0 | F20: IEC 62443-4-2 | G20: =FR1_IAC!A66 -> CR | H20: =FR1_IAC!B66 -> 1.11 | I20: No | L20: =FR1_IAC!J68 -> 1
